<mujoco model="wheeldog_p_v2">
    <compiler angle="radian"/>

    <visual>
        <headlight diffuse="1 1 1" ambient="0.3 0.3 0.3" specular="0 0 0"/>
        <rgba haze="0.15 0.25 0.35 1"/>
    </visual>

    <default>
        <default class="visual">
            <geom type="mesh" contype="0" conaffinity="0" group="2"/>
        </default>
        <default class="collision">
            <geom group="3"/>
        </default>
        <default class="collision_mesh">
            <geom contype="1" conaffinity="1" group="0"/>
        </default>
        <joint damping="1.0" stiffness="0.0" frictionloss="0.1" armature="0.01" />
        <default class='wheels'>
            <joint damping="0.0" stiffness="0.0" frictionloss="0.1" armature="0.01" />
        </default>
    </default>
    <worldbody>
        <geom name="ground" pos="0 0 0" size="50 50 0.1" type="plane"
        material="MatPlane" friction="0.8 0.02 0.01" condim="3"
        contype="2" conaffinity="1"/>
            <body name="base_link" pos="0.00000000 0.00000000 0.53208" quat="1 0 0 0">
                <inertial pos="-0.0001060231 -0.0024875751 -0.0273452117"
                            fullinertia="0.02005048393 0.07023562568 0.07321603090  1.6119174e-05 1.0224851e-10 1.9353034e-09"
                            mass="14.8631023851764"/>
                <site name="base_link_site" pos="0 0 0" size="0.01" rgba="0.2 0.2 0.2 1" />
                <joint name="base_free_joint" type="free" damping="0.0" />
                <site name='imu' size='0.01' pos='0.0 0 0.0'/>
                <geom name="base_link_collision" pos="0 0 0" quat="1.0 0.0 0.0 0.0" type="mesh" mesh="base_link" class="collision" />
                <geom name="base_link_visual" pos="0 0 0" quat="1.0 0.0 0.0 0.0" material="" type="mesh" mesh="base_link" class="visual" />
                 
                 <body name="FL_hip_link" pos="0.2175 0.0765 -0.007" quat="0.4999981633974483 0.49999999999662686 0.5000018366025516 0.49999999999662686">
                    <joint name="FL_hip_joint" pos="0 0 0" range="-0.6 0.6" axis="0 0 -1"/>
                    <inertial pos="-0.0275688215982023 -1.86415861600508E-05 0.0617298352753904" quat="1.0 0.0 0.0 0.0" mass="1.19412260585076" diaginertia="0.00144061026461053 0.000820229938948451 0.000995062737448315" />
                    <geom type="mesh" mesh="FL_hip_link"/>
                    
                    <body name="FL_shoulder_link" pos="-0.006575 0 0.069" quat="0.7071054825112363 0.0 0.7071080798594735 0.0">
                    <joint name="FL_shoulder_joint" pos="0 0 0" range="-1.6 1.53" axis="0 0 1"/>
                    <inertial pos="0.0281275413227622 -0.0195659508701502 0.058760545532628" quat="1.0 0.0 0.0 0.0" mass="1.68801596086804" diaginertia="0.00337952781207179 0.00464526087015627 0.00785172024842619" />
                    <geom type="mesh" mesh="FL_shoulder_link"/>

                    <body name="FL_leg_link" pos="0.20021 -0.19103 0.088975" quat="1.0 0.0 0.0 0.0">
                        <joint name="FL_leg_joint" pos="0 0 0" range="-0.64 1.35" axis="0 0 1"/>
                        <inertial pos="-0.0969838342042064 -0.133894108873387 -0.00613505118700663" quat="1.0 0.0 0.0 0.0" mass="0.435216170565793" diaginertia="0.0030751310636181 0.00160544973260313 0.00463879305789629" />
                        <geom type="mesh" mesh="FL_leg_link"/>

                        <body name="FL_wheel_link" pos="-0.16129 -0.23154 0.0035" quat="1.0 0.0 0.0 0.0">
                        <joint name="FL_wheel_joint" pos="0 0 0" axis="0 0 1" />
                        <inertial pos="2.06501482580279E-14 -6.16062756364499E-13 0.0336685249164005" quat="1.0 0.0 0.0 0.0" mass="1.06113838940194" diaginertia="0.00288100740736181 0.0028810074073618 0.00564119068491932" />
                        <geom type="mesh" mesh="FL_wheel_link"/>
                        </body>
                    </body>
                    </body>
                </body>
                <body name="FR_hip_link" pos="0.2175 -0.0765 -0.007" quat="0.4999981633974483 0.49999999999662686 0.5000018366025516 0.49999999999662686">
                    <joint name="FR_hip_joint" pos="0 0 0" range="-0.6 0.6" axis="0 0 -1"/>
                    <inertial pos="0.0275688215980941 1.86415861831435E-05 0.0617298352753904" quat="1.0 0.0 0.0 0.0" mass="1.19412260585075" diaginertia="0.00144061026461052 0.000820229938948446 0.000995062737448309" />
                    <geom type="mesh" mesh="FR_hip_link"/>

                    <body name="FR_shoulder_link" pos="0.006575 0 0.069" quat="0.7071054825112363 0.0 -0.7071080798594735 0.0">
                    <joint name="FR_shoulder_joint" pos="0 0 0" range="-1.6 1.53" axis="0 0 -1"/>
                    <inertial pos="-0.0601715937965866 -0.0388450000290335 0.0701878318631937" quat="1.0 0.0 0.0 0.0" mass="0.850883497306698" diaginertia="0.00277828373817426 0.0040659183520022 0.00677812532739976" />
                    <geom type="mesh" mesh="FR_shoulder_link"/>

                    <body name="FR_leg_link" pos="-0.20021 -0.19103 0.088975" quat="1.0 0.0 0.0 0.0">
                        <joint name="FR_leg_joint" pos="0 0 0" range="-0.64 1.35" axis="0 0 -1"/>
                        <inertial pos="0.0927856193356524 -0.127527546450413 -0.00512327308869451" quat="1.0 0.0 0.0 0.0" mass="0.408552378496402" diaginertia="0.00306797141874191 0.00159789148874654 0.00462477115994636" />
                        <geom type="mesh" mesh="FR_leg_link"/>

                        <body name="FR_wheel_link" pos="0.16129 -0.23154 0.0035" quat="1.0 0.0 0.0 0.0">
                        <joint name="FR_wheel_joint" pos="0 0 0" axis="0 0 -1" />
                        <inertial pos="4.98490138056695E-14 5.41122702202301E-13 0.0336685249163712" quat="1.0 0.0 0.0 0.0" mass="1.06113838940194" diaginertia="0.00288100740736181 0.0028810074073618 0.00564119068491933" />
                        <geom type="mesh" mesh="FR_wheel_link"/>
                        </body>
                    </body>
                    </body>
                </body>
                <body name="RL_hip_link" pos="-0.2175 0.0765 -0.007" quat="0.4983410734778166 0.5016516101066935 -0.49834475881632523 -0.5016516101066935">
                    <joint name="RL_hip_joint" pos="0 0 0" range="-0.6 0.6" axis="0 0 1"/>
                    <inertial pos="0.027568094627229 0.000201073322591672 0.0617298344121476" quat="1.0 0.0 0.0 0.0" mass="1.19412260528711" diaginertia="0.00144059200511364 0.00082024819743628 0.000995062736465972" />
                    <geom type="mesh" mesh="RL_hip_link"/>

                    <body name="RL_shoulder_link" pos="0.0065749 4.3487E-05 0.069" quat="0.7071054825112363 0.0 -0.7071080798594735 0.0">
                    <joint name="RL_shoulder_joint" pos="0 0 0" range="-1.6 1.53" axis="0 0 1"/>
                    <inertial pos="0.042034058215421 -0.0220931435228757 0.0659477936579857" quat="1.0 0.0 0.0 0.0" mass="2.22807961944994" diaginertia="0.00356825903124682 0.00483769693788184 0.00821821302094068" />
                    <geom type="mesh" mesh="RL_shoulder_link"/>
                    
                    <body name="RL_leg_link" pos="0.20921 -0.19103 0.088975" quat="1.0 0.0 0.0 0.0">
                        <joint name="RL_leg_joint" pos="0 0 0" range="-0.64 1.35" axis="0 0 1"/>
                        <inertial pos="-0.0948192053274108 -0.130608661936768 -0.00624901055590998" quat="1.0 0.0 0.0 0.0" mass="0.421048166077531" diaginertia="0.00307316867641144 0.00160349479927556 0.00463506760134561" />
                        <geom type="mesh" mesh="RL_leg_link"/>

                        <body name="RL_wheel_link" pos="-0.16129 -0.23154 0.0035" quat="1.0 0.0 0.0 0.0">
                        <joint name="RL_wheel_joint" pos="0 0 0" axis="0 0 1" />
                        <inertial pos="-1.20637877187857E-08 -2.85146184442198E-09 0.0336685248883136" quat="1.0 0.0 0.0 0.0" mass="1.06113838940194" diaginertia="0.00288100740736181 0.0028810074073618 0.00564119068491932" />
                        <geom type="mesh" mesh="RL_wheel_link"/>
                        </body>
                    </body>
                    </body>
                </body>
                <body name="RR_hip_link" pos="-0.2175 -0.0765 -0.007" quat="0.4983410734778166 0.5016516101066935 -0.49834475881632523 -0.5016516101066935">
                    <joint name="RR_hip_joint" pos="0 0 0" range="-0.6 0.6" axis="0 0 1"/>
                    <inertial pos="-0.0275680946223087 -0.000201074001019652 0.061729835282889" quat="1.0 0.0 0.0 0.0" mass="1.1941226052871" diaginertia="0.00144059200511363 0.000820248197436277 0.000995062736465969" />
                    <geom type="mesh" mesh="RR_hip_link"/>

                    <body name="RR_shoulder_link" pos="-0.0065748 -4.3511E-05 0.069" quat="0.7071016119976563 0.0023395956411939424 0.7071042093316763 -0.002339604235024375">
                    <joint name="RR_shoulder_joint" pos="0 0 0" range="-1.6 1.53" axis="0 0 -1"/>
                    <inertial pos="-0.0693510574764384 -0.0388432597265624 0.0701928553330247" quat="1.0 0.0 0.0 0.0" mass="0.850795559210917" diaginertia="0.00277828314348368 0.00406591775711992 0.00677812510250873" />
                    <geom type="mesh" mesh="RR_shoulder_link"/>

                    <body name="RR_leg_link" pos="-0.20921 -0.19103 0.088975" quat="1.0 0.0 0.0 0.0">
                        <joint name="RR_leg_joint" pos="0 0 0" range="-0.64 1.35" axis="0 0 -1"/>
                        <inertial pos="0.0948126850481408 -0.130611629665177 -0.00624844272089639" quat="1.0 0.0 0.0 0.0" mass="0.421045111740244" diaginertia="0.00307315113202937 0.00160352413322959 0.00463508040573333" />
                        <geom type="mesh" mesh="RR_leg_link"/>

                        <body name="RR_wheel_link" pos="0.16129 -0.23154 0.0035" quat="1.0 0.0 0.0 0.0">
                        <joint name="RR_wheel_joint" pos="0 0 0" axis="0 0 -1" />
                        <inertial pos="1.23223757031443E-08 -2.70793831802507E-09 0.0336685249457146" quat="1.0 0.0 0.0 0.0" mass="1.06113838940194" diaginertia="0.00288100740736181 0.0028810074073618 0.00564119068491933" />
                        <geom type="mesh" mesh="RR_wheel_link"/>
                        </body>
                    </body>
                </body>
            </body>
        </body>
    </worldbody>

    <asset>
        <texture type="skybox" builtin="gradient" rgb1="0.3 0.5 0.7" rgb2="0 0 0" width="512" height="3072"/>
        <texture type="2d" name="groundplane" builtin="checker" mark="edge" rgb1="0.2 0.3 0.4" rgb2="0.1 0.2 0.3" markrgb="0.8 0.8 0.8" width="300" height="300"/>
        <material name="MatPlane" texture="groundplane" texuniform="true" texrepeat="5 5" reflectance="0.2"/>
        <material name="rubber" rgba="0.4 0.4 0.4 1" shininess="0.5" reflectance="0.2"/>

        <mesh name="base_link" file="../mesh/base_link_fixed.STL"/>
        <mesh name="FL_hip_link"      file="../mesh/FL_hip_link.STL"/>
        <mesh name="FL_shoulder_link" file="../mesh/FL_shoulder_link.STL"/>
        <mesh name="FL_leg_link"      file="../mesh/FL_leg_link.STL"/>
        <mesh name="FL_wheel_link"    file="../mesh/FL_wheel_link.STL"/>
        <mesh name="FR_hip_link"      file="../mesh/FR_hip_link.STL"/>
        <mesh name="FR_shoulder_link" file="../mesh/FR_shoulder_link.STL"/>
        <mesh name="FR_leg_link"      file="../mesh/FR_leg_link.STL"/>
        <mesh name="FR_wheel_link"    file="../mesh/FR_wheel_link.STL"/>
        <mesh name="RL_hip_link"      file="../mesh/RL_hip_link.STL"/>
        <mesh name="RL_shoulder_link" file="../mesh/RL_shoulder_link.STL"/>
        <mesh name="RL_leg_link"      file="../mesh/RL_leg_link.STL"/>
        <mesh name="RL_wheel_link"    file="../mesh/RL_wheel_link.STL"/>
        <mesh name="RR_hip_link"      file="../mesh/RR_hip_link.STL"/>
        <mesh name="RR_shoulder_link" file="../mesh/RR_shoulder_link.STL"/>
        <mesh name="RR_leg_link"      file="../mesh/RR_leg_link.STL"/>
        <mesh name="RR_wheel_link"    file="../mesh/RR_wheel_link.STL"/>

    </asset>

    <actuator>
        <motor joint="FL_hip_joint"      name="FL_hip_joint"      ctrllimited="true" ctrlrange="-1000 1000" gear="1"/>
        <motor joint="FR_hip_joint"      name="FR_hip_joint"      ctrllimited="true" ctrlrange="-1000 1000" gear="1"/>
        <motor joint="RL_hip_joint"      name="RL_hip_joint"      ctrllimited="true" ctrlrange="-1000 1000" gear="1"/>
        <motor joint="RR_hip_joint"      name="RR_hip_joint"      ctrllimited="true" ctrlrange="-1000 1000" gear="1"/>
        <motor joint="FL_shoulder_joint" name="FL_shoulder_joint" ctrllimited="true" ctrlrange="-1000 1000" gear="-1"/>
        <motor joint="FR_shoulder_joint" name="FR_shoulder_joint" ctrllimited="true" ctrlrange="-1000 1000" gear="-1"/>
        <motor joint="RL_shoulder_joint" name="RL_shoulder_joint" ctrllimited="true" ctrlrange="-1000 1000" gear="1"/>
        <motor joint="RR_shoulder_joint" name="RR_shoulder_joint" ctrllimited="true" ctrlrange="-1000 1000" gear="1"/>
        <motor joint="FL_leg_joint"      name="FL_leg_joint"      ctrllimited="true" ctrlrange="-1000 1000" gear="-1.5"/>
        <motor joint="FR_leg_joint"      name="FR_leg_joint"      ctrllimited="true" ctrlrange="-1000 1000" gear="-1.5"/>
        <motor joint="RL_leg_joint"      name="RL_leg_joint"      ctrllimited="true" ctrlrange="-1000 1000" gear="-1.5"/>
        <motor joint="RR_leg_joint"      name="RR_leg_joint"      ctrllimited="true" ctrlrange="-1000 1000" gear="-1.5"/>
        <motor joint="FL_wheel_joint"    name="FL_wheel_joint"    ctrllimited="true" ctrlrange="-1000 1000" gear="1"/>     
        <motor joint="FR_wheel_joint"    name="FR_wheel_joint"    ctrllimited="true" ctrlrange="-1000 1000" gear="1"/>
        <motor joint="RL_wheel_joint"    name="RL_wheel_joint"    ctrllimited="true" ctrlrange="-1000 1000" gear="1"/>
        <motor joint="RR_wheel_joint"    name="RR_wheel_joint"    ctrllimited="true" ctrlrange="-1000 1000" gear="1"/>
    </actuator>

    <sensor>
        <framequat name="orientation" objtype="site" noise="0.1" objname="imu"/>
        <framepos name="position" objtype="site" noise="0.1" objname="imu"/>
        <gyro name="angular-velocity" site="imu" noise="0.2" cutoff="34.9"/>
        <velocimeter name="linear-velocity" site="imu" noise="0.1" cutoff="30"/>
        <accelerometer name="linear-acceleration" site="imu" noise="0.05" cutoff="157"/>
        <magnetometer name="magnetometer" site="imu"/>
    </sensor>

</mujoco>